<?xml version="1.0" ?>

<robot name="$(arg roboname)" xmlns:xacro="http://www.ros.org/wiki/xacro">

  <xacro:property name="PI" value="3.1415926835897931"/>

  <!-- base -->
  <xacro:property name="base_length" value="2.695"/>
  <xacro:property name="base_width" value="0.68"/>
  <xacro:property name="base_height" value="1.370"/>
  <xacro:property name="base_collision_height" value="0.875"/>
  <xacro:property name="base_mass" value="956"/>
  <xacro:property name="base_mass_ixx" value="343"/>
  <xacro:property name="base_mass_iyy" value="728"/>
  <xacro:property name="base_mass_izz" value="772"/>

  <!-- rear tyre -->
  <xacro:property name="rear_tyre_x" value="0.945"/>
  <xacro:property name="rear_tyre_y" value="0.642"/>
  <xacro:property name="rear_tyre_r" value="0.3"/>
  <xacro:property name="rear_tyre_length" value="0.165"/>
  <xacro:property name="rear_tyre_mass" value="20"/>
  <xacro:property name="rear_tyre_mass_ixx" value="0.5"/>
  <xacro:property name="rear_tyre_mass_iyy" value="0.9"/>
  <xacro:property name="rear_tyre_mass_izz" value="0.5"/> 

  <!-- front tyre -->
  <xacro:property name="front_tyre_x" value="0.923"/>
  <xacro:property name="front_tyre_y" value="0.642"/>
  <xacro:property name="front_tyre_r" value="0.3"/>
  <xacro:property name="front_tyre_length" value="0.165"/>
  <xacro:property name="front_tyre_mass" value="20"/>
  <xacro:property name="front_tyre_mass_ixx" value="0.5"/>
  <xacro:property name="front_tyre_mass_iyy" value="0.9"/>
  <xacro:property name="front_tyre_mass_izz" value="0.5"/>  

  <!-- steering -->
  <xacro:property name="str_angle" value="0.6"/>    
  <xacro:property name="str_length" value="0.01"/>
  <xacro:property name="str_radius" value="0.1"/>
  <xacro:property name="str_mass" value="5"/>
  <xacro:property name="str_mass_ixx" value="0.012"/>
  <xacro:property name="str_mass_iyy" value="0.025"/>
  <xacro:property name="str_mass_izz" value="0.012"/> 
    
    <!-- 车身 -->
    <link name="base_link">
        <!-- 碰撞体 -->
        <collision>
            <!-- 碰撞体原点位置和姿态 -->
            <origin xyz="0 0 ${base_collision_height}" rpy="0 0 0"/>
            <!-- 碰撞体几何形状 -->
            <geometry>
                <box size="${base_length} ${base_width} ${base_height}"/>
            </geometry>
        </collision>

        <!-- 可视化模型 -->
        <visual>
            <!-- 可视化模型原点位置和姿态 -->
            <origin xyz="0 0 ${base_collision_height}" rpy="0 0 0"/>
            <!-- 可视化模型几何形状 -->
            <geometry>
                <box size="${base_length} ${base_width} ${base_height}"/>
            </geometry>
        </visual>
    </link>

    <!-- 惯性关节 -->
    <joint name="inertial_joint" type="fixed">
        <!-- 关节父链 -->
        <parent link="base_link"/>
        <!-- 关节子链 -->
        <child link="main_mass"/>
        <!-- 关节原点位置和姿态 -->
        <origin xyz="0 0 0" rpy="0 0 0"/>
    </joint>

    <!-- 主质量链接 -->
    <link name="main_mass" type="fixed">
        <!-- 惯性信息 -->
        <inertial>
            <!-- 惯性原点位置和姿态 -->
            <origin xyz="0 0 0" rpy="0 0 0"/>
            <!-- 主质量 -->
            <mass value="${base_mass}"/>
            <!-- 惯性矩阵 -->
            <inertia
            ixx="${base_mass_ixx}"  ixy="0.000000"  ixz="0.000000"
            iyy="${base_mass_iyy}"  iyz="0.000000"
            izz="${base_mass_izz}"/>
        </inertial>
    </link>



    <!-- 后右轮  continuous which can rolling continue-->
    <joint name="rear_right_wheel_joint" type="continuous">
        <!-- 关节父链 -->
        <parent link="base_link"/>
        <!-- 关节子链 -->
        <child link="rear_right_wheel_link"/>
        <!-- 关节原点位置和姿态 -->
        <origin xyz="${-rear_tyre_x} ${-rear_tyre_y} ${rear_tyre_r}" rpy="0 0 0"/>
        <!-- 关节轴向 -->
        <axis xyz="0 1 0"/>
        <!-- 关节动力学属性 -->
        <dynamics damping="0.1"/>
        <!-- 关节限制 -->
        <limit effort="100000" velocity="10000"/>
        <!-- 关节属性 -->
        <joint_properties damping="0.0" friction="0.0"/>
    </joint>

    <!-- 后右轮链接 -->
    <link name="rear_right_wheel_link">
        <!-- 碰撞体 -->
        <collision>
            <!-- 碰撞体原点位置和姿态 -->
            <origin xyz="0 0 0" rpy="${PI/2} 0 0"/>
            <!-- 碰撞体几何形状 -->
            <geometry>
                <cylinder length="${rear_tyre_length}" radius="${rear_tyre_r}"/>
            </geometry>
        </collision>

        <!-- 可视化模型 -->
        <visual>
            <!-- 可视化模型原点位置和姿态 -->
            <origin xyz="0 0 0" rpy="${PI/2} 0 0"/>
            <!-- 可视化模型几何形状 -->
            <geometry>
                <cylinder length="${rear_tyre_length}" radius="${rear_tyre_r}"/>
            </geometry>
        </visual>

        <!-- 惯性信息 -->
        <inertial>
            <!-- 惯性原点位置和姿态 -->
            <origin xyz="0 0 0" rpy="0 0 0"/>
            <!-- 质量 -->
            <mass value="${rear_tyre_mass}"/>
            <!-- 惯性矩阵 -->
            <inertia
            ixx="${rear_tyre_mass_ixx}"  ixy="0.000000"  ixz="0.000000"
            iyy="${rear_tyre_mass_iyy}"  iyz="0.000000"
            izz="${rear_tyre_mass_izz}"/>
        </inertial>
    </link>


  <!--Rear Left Wheel-->
  <joint name="rear_left_wheel_joint" type="continuous">
    <parent link="base_link"/>
    <child link="rear_left_wheel_link"/>
    <origin xyz="${-rear_tyre_x} ${rear_tyre_y} ${rear_tyre_r}" rpy="0 0 0"/>
    <axis xyz="0 1 0"/>
    <dynamics damping="0.1"/>
    <limit effort="100000" velocity="10000" />
    <joint_properties damping="0.0" friction="0.0" />
  </joint>

  <link name="rear_left_wheel_link">
    <collision>
      <origin xyz="0 0 0" rpy="${PI/2} 0 0"/>
      <geometry>
        <cylinder length="${rear_tyre_length}" radius="${rear_tyre_r}"/>
      </geometry>
    </collision>

    <visual>
      <origin xyz="0 0 0" rpy="${PI/2} 0 0"/>
      <geometry>
        <cylinder length="${rear_tyre_length}" radius="${rear_tyre_r}"/>
      </geometry>
    </visual>

    <inertial>
      <origin xyz="0 0 0" rpy="0 0 0"/>
      <mass value="${rear_tyre_mass}"/>
      <inertia
        ixx="${rear_tyre_mass_ixx}"  ixy="0.000000"  ixz="0.000000"
        iyy="${rear_tyre_mass_iyy}"  iyz="0.000000"
        izz="${rear_tyre_mass_izz}"/>
    </inertial>
  </link> 

  <!--Front Right Steering-->
  <joint name="front_right_steering_joint" type="revolute">
    <parent link="base_link"/>
    <child link="front_right_steering_link"/>
    <origin xyz="${front_tyre_x} ${-front_tyre_y} ${front_tyre_r}" rpy="0 0 0"/>
    <axis xyz="0 0 1"/>
    <limit lower="${-str_angle}" upper="${str_angle}" effort="1000000.0" velocity="10000.0"/>
    <dynamics damping="10.0" friction="0.0"/>
  </joint>

  <link name="front_right_steering_link">
    <visual>
      <origin xyz="0 0 0" rpy="${PI/2} 0 0"/>
      <geometry>
        <cylinder length="${str_length}" radius="${str_radius}"/>
      </geometry>
    </visual>

    <inertial>
      <origin xyz="0 0 0" rpy="0 0 0"/>
      <mass value="${str_mass}"/>
      <inertia
      ixx="${str_mass_ixx}"  ixy="0.000000"  ixz="0.000000"
      iyy="${str_mass_iyy}"  iyz="0.000000"
      izz="${str_mass_izz}"/>
    </inertial>
  </link>


  <!--Front Right Wheel-->
  <joint name="front_right_wheel_joint" type="continuous">
    <parent link="front_right_steering_link"/>
    <child link="front_right_wheel_link"/>
    <origin xyz="0 0 0" rpy="0 0 0"/>
    <axis xyz="0 1 0"/>
    <dynamics damping="0.1"/>
    <limit effort="1000000" velocity="10000" />
    <joint_properties damping="0.0" friction="0.0" />
  </joint>

  <link name="front_right_wheel_link">
    <collision>
      <origin xyz="0 0 0" rpy="${PI/2} 0 0"/>
      <geometry>
        <cylinder length="${front_tyre_length}" radius="${front_tyre_r}"/>
      </geometry>
    </collision>

    <visual>
      <origin xyz="0 0 0" rpy="${PI/2} 0 0"/>
      <geometry>
        <cylinder length="${front_tyre_length}" radius="${front_tyre_r}"/>
      </geometry>  
    </visual>

    <inertial>
      <origin xyz="0 0 0" rpy="0 0 0"/>
      <mass value="${front_tyre_mass}"/>
      <inertia
        ixx="${front_tyre_mass_ixx}"  ixy="0.000000"  ixz="0.000000"
        iyy="${front_tyre_mass_iyy}"  iyz="0.000000"
        izz="${front_tyre_mass_izz}"/>
    </inertial>
  </link>

  <!--Front Left Steering-->
  <joint name="front_left_steering_joint" type="revolute">
    <parent link="base_link"/>
    <child link="front_left_steering_link"/>
    <origin xyz="${front_tyre_x} ${front_tyre_y} ${front_tyre_r}" rpy="0 0 0"/>
    <axis xyz="0 0 1"/>
    <limit lower="${-str_angle}" upper="${str_angle}" effort="1000000.0" velocity="10000.0"/>
    <dynamics damping="10.0" friction="0.0"/>
  </joint>

  <link name="front_left_steering_link">

    <visual>
      <origin xyz="0 0 0" rpy="${PI/2} 0 0"/>
      <geometry>
        <cylinder length="${str_length}" radius="${str_radius}"/>
      </geometry>
    </visual>

    <inertial>
      <origin xyz="0 0 0" rpy="0 0 0"/>
      <mass value="${str_mass}"/>
      <inertia
      ixx="${str_mass_ixx}"  ixy="0.000000"  ixz="0.000000"
      iyy="${str_mass_iyy}"  iyz="0.000000"
      izz="${str_mass_izz}"/>
    </inertial>
  </link>


  <!--Front Left Wheel-->
  <joint name="front_left_wheel_joint" type="continuous">
    <parent link="front_left_steering_link"/>
    <child link="front_left_wheel_link"/>
    <origin xyz="0 0 0" rpy="0 0 0"/>
    <axis xyz="0 1 0"/>
    <dynamics damping="0.1"/>
    <limit effort="1000000" velocity="10000" />
    <joint_properties damping="0.0" friction="0.0" />
  </joint>

  <link name="front_left_wheel_link">
    <collision>
      <origin xyz="0 0 0" rpy="${PI/2} 0 0"/>
      <geometry>
        <cylinder length="${front_tyre_length}" radius="${front_tyre_r}"/>
      </geometry>
    </collision>

    <visual>
      <origin xyz="0 0 0" rpy="${PI/2} 0 0"/>
      <geometry>
        <cylinder length="${front_tyre_length}" radius="${front_tyre_r}"/>
      </geometry>  
    </visual>

    <inertial>
      <origin xyz="0 0 0" rpy="0 0 0"/>
      <mass value="${front_tyre_mass}"/>
      <inertia
        ixx="${front_tyre_mass_ixx}"  ixy="0.000000"  ixz="0.000000"
        iyy="${front_tyre_mass_iyy}"  iyz="0.000000"
        izz="${front_tyre_mass_izz}"/>
    </inertial>
  </link>  


</robot>